Workbook

Sheet Leyenda
A1: CATÁLOGO DE INTERVENCIONES PARA ALZHEIMER · investigado con postura contraria al consenso · 12/10/2026
A3: Cómo se hizo: 15 temas, cada uno investigado por un agente con la instrucción de no fiarse del consenso, seguir el dinero, buscar donde el consenso no mira y no descartar nada por pequeño, antiguo, animal o heterodoxo. Fuentes: Europe PMC y PubMed por API, ClinicalTrials.gov, y webs, foros y libros heterodoxos.
A4: Nadie hace de juez. Las cifras se transcriben tal cual las da cada fuente. La columna "Dirección según la fuente" es lo que dice la propia fuente, no una opinión nuestra.
A5: Verificación documental: un segundo agente solo comprobó que la cita existe y que la cifra aparece en la fuente. No borró ni cambió nada; si una cifra difiere, lo anota en la columna "Verificación documental" y tú decides.
A6: Financiación y conflictos: lo que declara cada estudio; "no consta" significa que la fuente no lo dice, no que no exista.
A7: Columna Intervención (grupo): nombre canónico asignado por un agente para poder sumar filas de la misma intervención; la columna siguiente conserva el nombre tal como lo da la fuente. Hoja Filas: una fila por estudio o fuente. Hoja Resumen: cuenta por intervención con fórmulas sobre la hoja Filas (se recalcula sola si editas Filas). Hoja Dosieres: la tesis heterodoxa de cada tema, sus defensores, lo enterrado y las ideas para la app. Hoja Enterrado: ensayos sin resultados publicados y líneas abandonadas.
A8: Las conclusiones las saca la familia. Este archivo no es consejo médico; es material de investigación.
A9: Filas: 647. Temas: 15. Intervenciones distintas: 353.

Sheet Filas
A1: Tema | B1: Intervención (grupo) | C1: Intervención (tal como la nombra la fuente) | D1: Tradición o ángulo | E1: Estudio / fuente | F1: Tipo de fuente | G1: Diseño | H1: n | I1: Población | J1: Duración | K1: Dosis o protocolo | L1: Qué midió | M1: Resultado reportado (cifra tal cual) | N1: Dirección según la fuente | O1: Efectos adversos reportados | P1: Financiación y conflictos | Q1: Cómo probarlo en casa (según la fuente) | R1: Coste aprox. | S1: Verificación documental | T1: Identificador | U1: Enlace
A2: cobre_metales | B2: Cobre (suplemento oral) | C2: Cobre oral (orotato de Cu(II), 8 mg Cu/día) | D2: Hipótesis del déficit de cobre / suplementación | E2: Kessler H, Bayer TA, Bach D et al. 2008, J Neural Transm | F2: ensayo aleatorizado | G2: Fase 2 piloto, doble ciego, placebo | H2: 68 | I2: Alzheimer leve | J2: 12 meses | K2: 8 mg Cu/día como Cu-(II)-orotato dihidrato | L2: ADAS-Cog, MMSE | M2: Sin diferencias significativas en ADAS-Cog ni MMSE entre cobre y placebo; los autores concluyen que el cobre oral 'no tiene efecto perjudicial ni promotor' sobre la progresión | N2: sin cambio | O2: Bien tolerado | P2: no consta en el resumen. Promotor del registro NCT00608946: University Hospital, Saarland | S2: cita encontrada; cifra coincide (PMID 18587525; 8 mg Cu y conclusión de ausencia de efecto presentes) | T2: PMID 18587525; DOI 10.1007/s00702-008-0080-1; NCT00608946 | U2: https://europepmc.org/article/MED/18587525
A3: cobre_metales | B3: Cobre (suplemento oral) | C3: Cobre oral (orotato de Cu(II), 8 mg Cu/día) - biomarcadores LCR | D3: Hipótesis del déficit de cobre | E3: Kessler H, Pajonk FG, Bach D et al. 2008, J Neural Transm | F3: ensayo aleatorizado | G3: Fase 2 piloto, análisis de LCR del mismo ensayo | H3: 68 (mismo ensayo) | I3: Alzheimer leve | J3: 12 meses | K3: 8 mg Cu/día | L3: Abeta42, tau y fosfo-tau en LCR | M3: Abeta42 bajó 30% en placebo (P=0.001) y 10% en cobre (P=0.04); sin efecto sobre tau ni fosfo-tau; los autores señalan que podría indicar efecto positivo sobre un biomarcador, y que no hay efecto cognitivo | N3: mixto | O3: no consta | P3: no consta en el resumen | S3: cita encontrada; cifra coincide (PMID 18972062; 30%, 10%, P=0.001 y P=0.04 presentes) | T3: PMID 18972062; DOI 10.1007/s00702-008-0136-2; NCT00608946 | U3: https://europepmc.org/article/MED/18972062
A4: cobre_metales | B4: Cobre (agua de bebida) | C4: Cobre en agua de bebida (0.12 ppm) | D4: Hipótesis del cobre inorgánico en agua/tuberías | E4: Sparks DL, Friedland R, Petanceska S et al. 2006, Journal citado en PubMed (sin revista en API) | F4: animal | G4: Experimentos en conejos hipercolesterolémicos (Watanabe y alimentados con colesterol), beagles y ratones PS1/APP | H4: no consta | I4: Animales (conejos, perros, ratones transgénicos) | J4: no consta | K4: Cobre añadido al agua (0.12 ppm en experimentos previos del grupo, una décima del límite EPA); aluminio y zinc comparados | L4: Abeta cerebral | M4: El cobre en agua aumentó significativamente Abeta cerebral en los modelos; aluminio o zinc en agua destilada no tuvieron efecto significativo; el agua destilada redujo la acumulación esperada de Abeta en tres modelos | N4: empeora | O4: no consta | P4: NIH (NINDS NS45913, NIA AG023211). Conflictos no consta en el resumen | S4: cita encontrada; cifra no comprobable en el resumen (PMID 16886094; resultado cualitativo, título coherente) | T4: PMID 16886094 | U4: https://europepmc.org/article/MED/16886094
A5: cobre_metales | B5: Cobre (biomarcadores) | C5: Cobre cerebral bajo (déficit de cobre) | D5: Hipótesis del déficit de cobre en el cerebro | E5: Xu J, Church SJ, Patassini S et al. 2017, Metallomics | F5: observacional | G5: Medición post mortem por ICP-MS en 7 regiones cerebrales | H5: 9 Alzheimer y 13 controles | I5: Alzheimer (Braak IV-VI) vs controles | J5: post mortem | K5: ICP-MS de 8 metales esenciales y selenio | L5: Concentraciones de metales por región | M5: El cobre estaba disminuido en todas las regiones del cerebro con Alzheimer, al 52.8-70.2% de los valores control; los autores comparan con valores de la enfermedad de Menkes y proponen elevar el cobre cerebral como enfoque experimental | N5: empeora | O5: no aplica | P5: Neurological Foundation NZ, Health Research Council NZ, Maurice and Phyllis Paykel Trust, MRC UK. Conflictos no consta en el resumen | S5: cita encontrada; cifra coincide (PMID 28654115; cifras del resultado presentes en el resumen) | T5: PMID 28654115; DOI 10.1039/c7mt00074j | U5: https://europepmc.org/article/MED/28654115
A6: cobre_metales | B6: Cobre (biomarcadores) | C6: Cobre intercambiable en suero (ExcCu) como marcador | D6: Hipótesis del cobre libre / subtipo de Alzheimer por cobre | E6: Squitti R, Pal A, Ivanova ID et al. 2025, Biomolecules | F6: observacional | G6: Validación analítica CLSI de ensayo ICP-MS | H6: 154 controles, 82 Alzheimer, 10 enfermedad de Wilson | I6: Alzheimer, controles, Wilson | J6: no aplica | K6: Suero | L6: ExcCu y otros marcadores de cobre | M6: ExcCu significativamente elevado en Alzheimer vs controles (p<0.001); AUC 0.80 y especificidad 95% para distinguir Alzheimer de controles; índice REC AUC 0.88 para distinguir Alzheimer de Wilson | N6: empeora | O6: no aplica | P6: 'This research received no external funding' | S6: cita encontrada; cifra coincide (PMID 40563428; cifras del resultado presentes en el resumen) | T6: PMID 40563428; DOI 10.3390/biom15060788 | U6: https://europepmc.org/article/MED/40563428
A7: cobre_metales | B7: Cobre (biomarcadores) | C7: Ratio cobre/zinc y selenio/cobre séricos | D7: Ratio Cu/Zn | E7: Heinze T, Tuchtenhagen M, Knüppel S et al. 2025, J Alzheimers Dis (EPIC-Potsdam) | F7: observacional | G7: Casos y controles anidado en cohorte | H7: 128 casos (Alzheimer u otras demencias) y 512 controles | I7: Adultos, seguimiento ~15.7 años | J7: ~15.7 años desde basal | K7: Suero basal | L7: Mn, Fe, Cu, Zn, Se, I, cobre intercambiable, MDA, 3-NT | M7: Cu/Zn alto asociado a mayor incidencia (OR=2.1, IC95% 1.1-4.1); Se/Cu alto asociado inversamente (OR=0.72, IC95% 0.56-0.92); mujeres casos con tendencia a más Cu y CuEXC | N7: mixto | O7: no aplica | P7: DFG FOR2558, BMFT, Deutsche Krebshilfe, FONIS-ANID Chile, Unión Europea | S7: cita encontrada; cifra coincide (PMID 40267333; cifras del resultado presentes en el resumen) | T7: PMID 40267333; DOI 10.1177/13872877251333726 | U7: https://europepmc.org/article/MED/40267333
A8: cobre_metales | B8: Cobre (dieta) | C8: Cobre de la dieta | D8: Cobre dietético | E8: Wu X, Chen Y, Liu H et al. 2026, J Nutr Health Aging (UK Biobank) | F8: observacional | G8: Cohorte prospectiva + transversal | H8: 126 660 | I8: Adultos UK Biobank, edad media 56.14 | J8: mediana 13.34 años | K8: Mediana de ingesta 1.33 mg/día | L8: Alzheimer incidente (619 casos), cognición, RM | M8: Asociación en U: riesgo más bajo con 1.57 mg/día; ingesta >=3 mg/día HR=2.73 (IC95% 1.53-4.87) frente a referencia 1-2 mg/día; también mayor riesgo con ingestas bajas | N8: mixto | O8: no aplica | P8: no consta en el resumen | S8: cita encontrada; cifra coincide (PMID 42102760; cifras del resultado presentes en el resumen) | T8: PMID 42102760; DOI 10.1016/j.jnha.2026.100868 | U8: https://europepmc.org/article/MED/42102760
A9: cobre_metales | B9: Cobre (evitar exposición) | C9: Evitar cobre divalente ingerido (pastillas multimineral, agua de tuberías de cobre) | D9: Hipótesis Copper-2 de Brewer | E9: Brewer GJ 2019, Exp Biol Med (PMC6405820) | F9: revision | G9: Revisión de hipótesis de un solo autor | H9: no aplica | I9: no aplica | J9: no aplica | K9: Evitar multiminerales con cobre; instalar dispositivo de eliminación de cobre en el grifo de beber/cocinar; no hace falta quitar la tubería | L9: Mecanismo y evidencia animal/humana citada | M9: Autor afirma que el cobre-2 es 'muy tóxico para la cognición' y que 'la mayoría de AD puede prevenirse'; también dice 'The Copper-2 Hypothesis is still a hypothesis' | N9: mejora | O9: no aplica | P9: El autor declara no tener conflictos ni financiación (según PMC). Una búsqueda web asocia a Brewer con Adeona Pharmaceuticals (zinc); no verificado en este artículo | S9: cita encontrada; cifra no comprobable en el resumen (PMID 30727765; resultado cualitativo) | T9: PMID 30727765; DOI 10.1177/1535370219827907 | U9: https://pmc.ncbi.nlm.nih.gov/articles/PMC6405820
A10: cobre_metales | B10: Zinc (suplemento) | C10: Zinc (acetato) 135 mg/día 12 semanas luego 65 mg/día | D10: Terapia de zinc para bajar cobre (como en Wilson) | E10: Squitti R, Benussi A, Fostinelli S et al. 2025, Biomolecules (ZINCAiD) | F10: ensayo aleatorizado | G10: Fase 2, doble ciego, placebo, 2:1 | H10: 48 aleatorizados (39 con datos completos de ceruloplasmina) | I10: Deterioro cognitivo leve por Alzheimer | J10: 24 semanas | K10: 135 mg/día elemental 12 semanas, luego 65 mg/día | L10: CC2 (primario), MMSE, CDR-SB | M10: Análisis primario sin diferencias; post hoc: 12 pacientes (31%) 'respondedores' (>=20% menos ceruloplasmina) mantuvieron estabilidad; el grupo no respondedor+placebo declinó (CC2 Δ=-2.72; interacción p=0.030); CDR-SB p=0.017; MMSE tendencia p=0.09 | N10: mixto | O10: Síntomas gastrointestinales leves en 8; 4 abandonos; 2 eventos graves, ambos en placebo | P10: Alzheimer's Association (PTC-19-602325), Italian Ministry of Health. Conflictos no consta en el resumen | S10: cita encontrada; cifra coincide (PMID 41008575; cifras del resultado presentes en el resumen) | T10: PMID 41008575; DOI 10.3390/biom15091268; EudraCT 2019-000604-15 | U10: https://europepmc.org/article/MED/41008575
A11: cobre_metales | B11: Zinc (biomarcadores) | C11: Déficit de zinc en sangre | D11: Zinc | E11: Brewer GJ, Kanzer SH, Zimmerman EA et al. 2010, Am J Alzheimers Dis Other Demen | F11: observacional | G11: Casos y controles | H11: 29 Alzheimer, 30 Parkinson, 29 controles | I11: Mayores de 50 | J11: no aplica | K11: Sin suplementos 30 días antes | L11: Zinc en sangre y orina | M11: Zinc en sangre significativamente menor en Alzheimer y Parkinson que en controles; excreción urinaria sin diferencia; los autores lo atribuyen a insuficiencia nutricional | N11: empeora | O11: no aplica | P11: no consta en el resumen | S11: cita encontrada; cifra no comprobable en el resumen (PMID 20841345; resultado cualitativo) | T11: PMID 20841345; DOI 10.1177/1533317510382283 | U11: https://europepmc.org/article/MED/20841345
A12: cobre_metales | B12: Zinc (biomarcadores) | C12: Zinc sérico (metaanálisis) | D12: Zinc / cobre | E12: Ventriglia M, Brewer GJ, Simonelli I et al. 2015, J Alzheimers Dis | F12: revision | G12: Metaanálisis de 27 estudios | H12: 777 Alzheimer y 1,728 controles (suero) | I12: Alzheimer | J12: 1983-2014 | K12: no aplica | L12: Zinc en suero, plasma y LCR | M12: Zinc sérico significativamente menor en Alzheimer; en los 6 estudios con edad pareada SMD=-0.55 (IC95% -1.18 a 0.09; p=0.094; I2=91%); heterogeneidad muy alta | N12: mixto | O12: no aplica | P12: no consta en el resumen | S12: cita encontrada; cifra coincide (PMID 25697706; cifras del resultado presentes en el resumen) | T12: PMID 25697706; DOI 10.3233/jad-141296 | U12: https://europepmc.org/article/MED/25697706
A13: cobre_metales | B13: Zinc (suplemento) | C13: Zinc cisteína de liberación sostenida (CopperProof-2) | D13: Zinc para bajar cobre | E13: Registro ClinicalTrials.gov NCT01099332 (Adeona Pharmaceuticals) | F13: registro de ensayo | G13: Fase 1/2, aleatorizado, doble ciego, placebo | H13: 60 previstos | I13: Alzheimer leve, 55-90 años | J13: 6 meses | K13: Zinc cisteína una vez al día | L13: Metales en suero por absorción atómica | M13: Estado UNKNOWN; sin resultados publicados en el registro | N13: no aplica | O13: no aplica | P13: Promotor: Adeona Pharmaceuticals (industria) | S13: cita encontrada; cifra coincide (NCT01099332; n=60, estado UNKNOWN, sin resultados) | T13: NCT01099332 | U13: https://clinicaltrials.gov/study/NCT01099332
... A45: cobre_metales | B45: Cobre (objeto llevado) | C45: Pulsera de cobre | D45: Cobre llevado en el cuerpo | E45: Richmond SJ, Gunadasa S, Bland M, Macpherson H. 2013, PLoS One | F45: ensayo aleatorizado | G45: Cruzado doble ciego, 4 dispositivos | H45: 70 | I45: Artritis reumatoide (no Alzheimer) | J45: no consta | K45: Pulsera de cobre | L45: Dolor, inflamación, función | M45: Sin diferencias significativas (P>0.05) frente a placebo | N45: sin cambio | O45: no consta | P45: NIHR NF-SI-0507-10133 | S45: cita encontrada; cifra coincide (PMID 24066023; cifra del resultado presente en el resumen; título coincide) | T45: PMID 24066023; ISRCTN51459023 | U45: https://europepmc.org/article/MED/24066023
A46: psicodelicos | B46: Psilocibina | C46: Psilocibina (setas, cepa Enigma) dosis alta | D46: Caso clínico privado en Brasil; clínica psiquiátrica | E46: Lago M, Cerveira M, Simonet JX. 2026. Front Neurosci | F46: caso | G46: Informe de caso, sin control ni placebo | H46: 1 | I46: Mujer de unos 80 años, Alzheimer avanzado de 10 años (5 años de habla monosilábica), japonesa-estadounidense | J46: Sesión 1; sesión 2 un mes después; seguimiento de días y semanas | K46: Sesión 1: 5 g de setas con psilocibina por vía oral; sesión 2: 3 g un mes después | L46: Observación clínica e informe de cuidadores; sin escalas cognitivas, sin imagen, sin biomarcadores | M46: A las ~19 h de la dosis apareció habla autobiográfica espontánea (~4 h). Días y semanas después: continencia urinaria restablecida (llevaba 5 años sin ella), caminar autónomo, vestirse sola, contacto visual y sonrisas, recuerdo contextual (preguntó dónde estaba una persona concreta). Sin cifras. Los autores dicen que no implica reversión de la enfermedad y que es transitorio | N46: mejora | O46: Fase aguda: sudoración profusa, sospecha de hipertermia (no medida), estado de sueño profundo prolongado. Sin efectos graves persistentes en el seguimiento según los autores | P46: Sin financiación declarada; sin conflictos declarados. No dice quién proporcionó las setas | Q46: Los propios autores dicen que no es una recomendación de uso sin supervisión; la fuente describe 5 g de setas secas orales | S46: cita encontrada; cifra coincide. PMID 42292331; DOI 10.3389/fnins.2026.1813281 (5 g y ~19 h aparecen en el resumen) | T46: PMID 42292331; DOI 10.3389/fnins.2026.1813281 | U46: https://pubmed.ncbi.nlm.nih.gov/42292331/
A47: psicodelicos | B47: Psilocibina | C47: Psilocibina 25 mg x2 en deterioro cognitivo leve amnésico | D47: Toronto (CAMH), PET de densidad sináptica SV2A | E47: Bukovsky D, Amaev A, ... Gerretsen P. 2025. Alzheimers Dement 21(S5):e101101 (resumen de congreso) | F47: ensayo aleatorizado | G47: Doble ciego, placebo, aleatorizado, con PET [18F]SynVesT; datos preliminares | H47: Diseño previsto: aMCI y controles sanos; datos piloto de 2 aMCI + 3 controles | I47: Deterioro cognitivo leve amnésico (media 71 años, MoCA 22) y sanos | J47: Dos dosis separadas una semana; PET pre y 1 semana post; evaluaciones a 1, 4 y 12 semanas | K47: Dos dosis de 25 mg de psilocibina o placebo con una semana de diferencia, con médico y terapeuta | L47: Seguridad, viabilidad, tolerabilidad; densidad sináptica en hipocampo y corteza prefrontal; cognición | M47: Todos completaron sin incidentes; bien tolerada; sin eventos adversos graves ni inesperados. La eficacia aún no se reporta (ciego sin abrir) | N47: sin cambio | O47: Mareo (n=4), percepción alterada (n=3), resueltos sin secuelas | P47: No consta en el resumen; autores del Centre for Addiction and Mental Health, Toronto | S47: cita encontrada; cifra no comprobable en el resumen. PMCID PMC12740486; DOI 10.1002/alz70859_101101 (sin resumen en Europe PMC) | T47: PMCID PMC12740486; DOI 10.1002/alz70859_101101 | U47: https://pmc.ncbi.nlm.nih.gov/articles/PMC12740486/
A48: psicodelicos | B48: Psilocibina | C48: Psilocibina 0,5 mg/kg mensual en ratones 5xFAD | D48: Neuroplasticidad, neurogénesis, antiinflamatorio | E48: Madhu LN, ... Shetty AK. 2025. Alzheimers Dement 21(S5):e100589 (resumen congreso) | F48: animal | G48: Ratones macho 5xFAD de 3 meses tratados 4 meses; comparados con vehículo y controles | H48: No consta en el resumen | I48: Ratones modelo de Alzheimer 5xFAD | J48: Dosis mensual durante 4 meses; pruebas un mes después; eutanasia a los 8 meses | K48: Psilocibina 0,5 mg/kg una vez al mes | L48: Pruebas conductuales, neuroinflamación, neurogénesis del hipocampo, sinapsis, placas de beta-amiloide, proteómica | M48: Mejor discriminación de cambios en el entorno, separación de patrones, memoria de reconocimiento asociativo y ausencia de anhedonia vs vehículo; menos hipertrofia astrocítica, inflamasomas NLRP3, p38 MAPK y cGAS-STING; más neuronas nuevas y señal BDNF-ERK-CREB; 16 proteínas sobreexpresadas en el proteoma del hipocampo. NO redujo las placas de amiloide | N48: mixto | O48: No consta | P48: No consta en el resumen; Texas A&M University | S48: cita encontrada; cifra no comprobable en el resumen. PMCID PMC12739712; DOI 10.1002/alz70859_100589 (sin resumen; título coincide) | T48: PMCID PMC12739712; DOI 10.1002/alz70859_100589 | U48: https://pmc.ncbi.nlm.nih.gov/articles/PMC12739712/
A49: psicodelicos | B49: LSD | C49: LSD a dosis bajas (5, 10, 20 microgramos) cada 4 días | D49: Microdosis; ensayo fase 1 de la empresa Eleusis para Alzheimer | E49: Family N, ... Raz S. 2020. Psychopharmacology | F49: ensayo aleatorizado | G49: Fase 1, doble ciego, placebo, aleatorizado, 4 grupos | H49: 48 (12 por grupo) | I49: Voluntarios sanos mayores, edad media 62,9 años | J49: 21 días, 6 dosis (cada 4 días) | K49: LSD oral 5, 10 o 20 microgramos o placebo en 6 ocasiones | L49: Seguridad, tolerabilidad, farmacocinética, cognición, equilibrio, propiocepción | M49: Niveles de LSD indetectables en el grupo de 5 microgramos; pico a los 30 min en 10 y 20. Frecuencia de eventos adversos no superior a placebo. Sin deterioro en cognición, equilibrio y propiocepción | N49: sin cambio | O49: Frecuencia no mayor que placebo. Una revisión posterior (Vann Jones 2020) cita dolor de cabeza más frecuente con LSD en un estudio en mayores | P49: Financiado por Eleusis Benefit Corporation (declarado en la ficha de financiación de Europe PMC) | Q49: Dosis de la fuente: 5-20 microgramos orales cada 4 días durante 21 días, en entorno clínico | R49: No consta | S49: cita encontrada; cifra coincide. PMID 31853557; DOI 10.1007/s00213-019-05417-7 | T49: PMID 31853557; DOI 10.1007/s00213-019-05417-7 | U49: https://pubmed.ncbi.nlm.nih.gov/31853557/
A50: psicodelicos | B50: Psicodélicos (general) | C50: Psicodélicos y microdosis en Alzheimer (revisión mecanística) | D50: Revisión de defensores del potencial neuroplástico; Cornwall, Reino Unido | E50: Vann Jones SA, O'Kelly A. 2020. Front Synaptic Neurosci. Psychedelics as a Treatment for Alzheimer's Disease Dementia | F50: revision | G50: Mini-revisión | H50: No aplica | I50: Alzheimer; citan estudios en sanos y animales | J50: No aplica | K50: Cita LSD 5/10/20 microgramos (Hutten 2020), 6,5/13/26 (Bershad 2019), 5-20 cada 5 días (Family 2020); psilocibina PET 15-20 mg aumentó ~25% el metabolismo global de glucosa en voluntarios sanos | L50: Mecanismos propuestos: 5-HT2A, neurogénesis hipocampal, SIRT1, biogénesis mitocondrial, gamma, reorganización de redes | M50: En modelo de estreptozotocina en roedores agonistas 5-HT1A y 5-HT2A fueron neuroprotectores (sin cifras en el texto leído). Dicen que no hay estudios controlados de microdosis en deterioro cognitivo | N50: mixto | O50: Riesgos que citan: taquifilaxia tras 4 dosis diarias seguidas; dosis altas podrían suprimir la neurogénesis del hipocampo; reducción de atención a dosis altas; con LSD 20 microgramos menor concentración horas después; ratas con LSD crónico alto hiperactivas y asociales | P50: Sin conflictos comerciales declarados; financiación no consta | S50: cita encontrada; cifra no comprobable en el resumen. PMCID PMC7472664 -> PMID 32973482; DOI 10.3389/fnsyn.2020.00034 (título y año 2020 coinciden) | T50: PMCID PMC7472664 | U50: https://pmc.ncbi.nlm.nih.gov/articles/PMC7472664/
A51: psicodelicos | B51: Psilocibina | C51: Psilocibina sintética vs extracto de seta psicodélica completa | D51: Efecto séquito: el extracto completo supera al compuesto aislado | E51: Shahar O, ... Lifschytz T, Lerer B. 2024. Mol Psychiatry | F51: animal | G51: Ratones macho C57Bl/6j, western blot de proteínas sinápticas y metabolómica | H51: No consta en el resumen | I51: Ratones sanos (no modelo de Alzheimer) | J51: 3 y 11 días tras tratamiento | K51: Psilocibina sintética (PSIL) vs extracto de seta psicodélica (PME) | L51: GAP43, PSD95, sinaptofisina, SV2A en 4 regiones; metabolómica de corteza prefrontal | M51: A los 11 días PSIL y PME aumentaron GAP43 en corteza frontal (p=0,019; p=0,039) e hipocampo (p=0,015; p=0,027) y sinaptofisina en hipocampo (p=0,041; p=0,05) y amígdala (p=0,035; p=0,004). SV2A: PSIL amígdala p=0,036; PME hipocampo p=0,014. A los 3 días mínimo aumento. ANOVA anidado: PME aumentó las 4 proteínas en todas las áreas; PSIL solo PSD95 y SV2A en hipocampo y amígdala. Los autores concluyen efecto más potente y prolongado con PME | N51: mejora | O51: No consta | P51: Becas citadas: Back of the Yards Algae Sciences (BYAS) y Parow Entheobiosciences (empresas) | S51: cita encontrada; cifra coincide. PMID 38378926; DOI 10.1038/s41380-024-02477-w (13 de 13 cifras presentes) | T51: PMID 38378926; DOI 10.1038/s41380-024-02477-w | U51: https://pubmed.ncbi.nlm.nih.gov/38378926/
A52: psicodelicos | B52: DMT | C52: DMT con antioxidantes vegetales (withanona, apigenina, bacósido A, baicalina, timoquinona) | D52: Combinación de psicodélico y plantas | E52: Jarne-Ferrer J, Pallàs M, Griñán-Ferré C, Bellver-Sanchis A. 2025. Cells | F52: celula | G52: Gusano C. elegans transgénico modelo de Alzheimer | H52: No consta | I52: Modelo de C. elegans de Alzheimer (no mamífero) | J52: No consta en el resumen | K52: Combinaciones de los compuestos con N,N-DMT; dosis no consta en el resumen | L52: Motilidad, tinción de tioflavina S (placas), supervivencia bajo estrés oxidativo | M52: La combinación fue más eficaz que los compuestos solos: menos defectos de motilidad, menos carga de placa de Abeta, mayor supervivencia al estrés oxidativo, efecto sinérgico (sin cifras en el resumen) | N52: mejora | O52: No consta | P52: Ministerio de Economía (AEI) y Generalitat de Catalunya; conflictos no consta | S52: cita encontrada; cifra no comprobable en el resumen. PMID 40558561; DOI 10.3390/cells14120934 (título coincide; resumen sin cifras) | T52: PMID 40558561; DOI 10.3390/cells14120934 | U52: https://pubmed.ncbi.nlm.nih.gov/40558561/
A53: psicodelicos | B53: Ketamina | C53: Ketamina a dosis baja en ratones de Alzheimer | D53: Línea de Brasil (UFRJ) sobre ketamina y riesgo de Alzheimer | E53: Lima-Filho RAS, ... Lourenco MV. 2025. Alzheimers Dement 21(S1):e100276 (resumen congreso) | F53: animal | G53: Ratones inyectados con oligómeros de Abeta y ratones transgénicos APP/PS1; RNA-seq | H53: No consta | I53: Ratones modelo de Alzheimer y salvajes | J53: Dosis única; tratamiento crónico de 35 días | K53: Ketamina 10 mg/kg dosis única; crónica 35 días en APP/PS1 | L53: Memoria, amiloide hipocampal, morfología glial, transcriptoma | M53: La dosis única protegió del daño de memoria por Abeta. En APP/PS1 el tratamiento crónico no tuvo impacto en memoria. La ketamina crónica en ratones salvajes indujo un perfil transcripcional similar al genotipo APP/PS1 (>700 genes comunes); >200 genes comunes regulados en sentido opuesto, solo 12 en el mismo sentido; más microglía alrededor de placas. Los autores piden cautela con ketamina en personas en riesgo | N53: mixto | O53: No consta | P53: No consta en el resumen | S53: cita encontrada; cifra no comprobable en el resumen. PMCID PMC12726942; DOI 10.1002/alz70855_100276 (título coincide; sin resumen) | T53: PMCID PMC12726942; DOI 10.1002/alz70855_100276 | U53: https://pmc.ncbi.nlm.nih.gov/articles/PMC12726942/
A54: psicodelicos | B54: Hidroxinorketamina | C54: Hidroxinorketamina (2R,6R)-HNK, metabolito de la ketamina | D54: Anhedonia en Alzheimer (China) | E54: Yang S, Guo B, Deng D, Zhang Y, Zhou Q. 2026. Biochem Biophys Res Commun | F54: animal | G54: Ratones APP/PS1 de 8 meses, dosis única | H54: No consta en el resumen | I54: Ratones modelo de Alzheimer | J54: Dosis única | K54: (2R,6R)-HNK una sola dosis | L54: Test de preferencia por sacarosa (anhedonia); relación excitación/inhibición prefrontal; eEF2, BDNF, GLT-1 | M54: Los ratones APP/PS1 mostraron anhedonia marcada y una dosis única de HNK la alivió rápidamente; aumentó la relación E/I prefrontal, redujo eEF2 fosforilado y elevó BDNF y GLT-1 | N54: mejora | O54: No consta | P54: No consta en el resumen | S54: cita encontrada; cifra no comprobable en el resumen. PMID 42800170; DOI 10.1016/j.bbrc.2026.154535 (título coincide; resumen sin cifras) | T54: PMID 42800170; DOI 10.1016/j.bbrc.2026.154535 | U54: https://pubmed.ncbi.nlm.nih.gov/42800170/
A55: psicodelicos | B55: Psicodélicos (general) | C55: Psicodélicos en organoides cerebrales humanos | D55: Proteómica y neuroplasticidad | E55: Androni X, Boyd RJ, Rosenberg PB, Mahairaki V. 2025. Front Dement | F55: revision | G55: Mini-revisión sobre organoides | H55: No aplica | I55: Organoides cerebrales humanos | J55: No aplica | K55: No consta | L55: Cambios moleculares y metabólicos por psicodélicos en organoides | M55: Resume la literatura de organoides; sin cifras en el resumen. Presenta los psicodélicos como candidatos neuroplastogénicos y antiinflamatorios | N55: mejora | O55: No consta | P55: Ficha de financiación: NIA NIH; conflictos no consta | S55: cita encontrada; cifra no comprobable en el resumen. PMID 40832110; DOI 10.3389/frdem.2025.1605051 (título coincide; resumen sin cifras) | T55: PMID 40832110; DOI 10.3389/frdem.2025.1605051 | U55: https://pubmed.ncbi.nlm.nih.gov/40832110/
A56: psicodelicos | B56: Psicodélicos (general) | C56: Psicodélicos serotoninérgicos (LSD, psilocibina, DMT, mescalina, ayahuasca) en demencia | D56: Revisión narrativa Coimbra, Portugal | E56: Vieira-Andrade J, Marques I, Brito M. 2026. Int J Neuropsychopharmacol 29(S1):i229 (resumen CINP) | F56: revision | G56: Revisión narrativa en PubMed y Scopus | H56: No aplica | I56: Demencia, Alzheimer y modelos | J56: No aplica | K56: Cita LSD 5-20 microgramos cada 5 días 4 semanas en mayores | L56: Evidencia clínica y preclínica | M56: Dicen que no hay ensayos publicados en pacientes con demencia; un piloto (NCT04123314) en marcha; en mayores no hubo diferencia en eventos adversos entre placebo y LSD 5-20 microgramos cada 5 días 4 semanas; un estudio murino halló efectos neuroprotectores independientes y sinérgicos de agonistas 5-HT1A y 5-HT2A en hipocampo | N56: mixto | O56: No consta | P56: No consta | S56: cita encontrada; cifra no comprobable en el resumen. PMCID PMC13556823; DOI 10.1093/ijnp/pyag040.424 (título y año 2026 coinciden; sin resumen) | T56: PMCID PMC13556823; DOI 10.1093/ijnp/pyag040.424 | U56: https://pmc.ncbi.nlm.nih.gov/articles/PMC13556823/
A57: psicodelicos | B57: Dronabinol | C57: Dronabinol (THC sintético) 10 mg/día | D57: Cannabinoides para agitación; Johns Hopkins y otros 5 centros | E57: Rosenberg PB, Amjad H, ... 2026. Am J Geriatr Psychiatry (THC-AD) | F57: ensayo aleatorizado | G57: Paralelo, doble ciego, placebo, 5 centros, 2017-2024 | H57: 75 (84% completó) | I57: Alzheimer con agitación, deterioro grave (MMSE/SIB-8) | J57: 3 semanas | K57: Dronabinol hasta 10 mg/día en dos tomas, añadido a su medicación | L57: Pittsburgh Agitation Scale (PAS) y NPI-C agitación/agresión; secundarios sueño, AVD, CMAI, cognición, lorazepam o trazodona a demanda | M57: Diferencia entre brazos en la caída semanal de PAS -0,74 (EE 0,3; p=0,015; tamaño del efecto 0,53); NPI-C A/A -1,26 (EE 0,67; p=0,094; tamaño 0,36, no significativo). Ningún secundario difirió (sueño, AVD, CMAI, cognición, intoxicación, medicación a demanda) | N57: mejora | O57: Sin más eventos adversos que placebo salvo somnolencia | P57: Subvenciones NIA/NIH; conflictos no consta en el resumen | Q57: Dosis de la fuente: titulación hasta 10 mg/día en dos tomas durante 3 semanas | S57: cita encontrada; cifra coincide. PMID 41350162; DOI 10.1016/j.jagp.2025.10.011; NCT02792257 (75 y cifras PAS/NPI-C presentes; registro indica 84 inscritos) | T57: PMID 41350162; NCT02792257; DOI 10.1016/j.jagp.2025.10.011 | U57: https://pubmed.ncbi.nlm.nih.gov/41350162/
A58: psicodelicos | B58: Nabilona | C58: Nabilona 1-2 mg/día | D58: Cannabinoide sintético; Sunnybrook, Toronto | E58: Herrmann N, ... Lanctôt KL. 2019. Am J Geriatr Psychiatry | F58: ensayo aleatorizado | G58: Cruzado, doble ciego, placebo, 6 semanas por fase + 1 semana de lavado | H58: 39 | I58: Alzheimer moderado-grave (sMMSE ≤24) con agitación en residencia y clínicas | J58: 14 semanas | K58: Nabilona objetivo 1-2 mg (media 1,6 ± 0,5 mg) oral | L58: CMAI (primario), NPI-NH, malestar del cuidador, sMMSE, SIB, CGIC | M58: Diferencias a favor de nabilona: CMAI b=-4,0 (IC95 -6,5 a -1,5; p=0,003); NPI-NH total b=-4,6 (p=0,004); malestar cuidador b=-1,7 (p=0,041); sMMSE b=1,1 (p=0,026). En quienes hicieron SIB (n=25) la diferencia favoreció a placebo (b=-4,6; p=0,003). CGIC mejoría 47% vs 23% (p=0,09) | N58: mixto | O58: Más sedación con nabilona (45%) vs placebo (16%), p=0,02; sedación que obliga a parar no diferente (p=0,22) | P58: Subvenciones: Alzheimer Society, NIA, CIHR, Alzheimer's Drug Discovery Foundation | Q58: Dosis de la fuente: 1-2 mg/día en cápsula, ensayo supervisado | S58: cita encontrada; cifra coincide. PMID 31182351; DOI 10.1016/j.jagp.2019.05.002 (15 de 15 cifras presentes) | T58: PMID 31182351; DOI 10.1016/j.jagp.2019.05.002 | U58: https://pubmed.ncbi.nlm.nih.gov/31182351/
A59: psicodelicos | B59: Nabilona | C59: Nabilona: análisis secundario de síntomas no agitación | D59: Mismo ensayo de Sunnybrook, apetito, ánimo, ansiedad | E59: Pan TJ, Wang HJ, Herrmann N, ... Lanctôt KL. 2025. Alzheimers Dement 21(S3):e105775 (resumen) | F59: ensayo aleatorizado | G59: Análisis secundario del cruzado de 14 semanas | H59: 39 (media 87 años) | I59: Alzheimer moderado-grave con agitación | J59: 6 semanas por fase | K59: Nabilona 1,6 ± 0,5 mg/día | L59: Subescalas del NPI-NH distintas de agitación | M59: Mayor descenso de ansiedad (b=-1,12; EE 0,55; p=0,048) y depresión (b=-0,68; EE 0,31; p=0,039); cambio en apetito/hábitos de comida (b=2,00; EE 0,55; p<0,001), dirección (más o menos apetito) poco clara según los autores | N59: mejora | O59: No consta en este resumen | P59: No consta en este resumen; Sunnybrook | S59: cita encontrada; cifra no comprobable en el resumen. PMCID PMC12739322; DOI 10.1002/alz70857_105775 (título coincide; sin resumen) | T59: PMCID PMC12739322; DOI 10.1002/alz70857_105775 | U59: https://pmc.ncbi.nlm.nih.gov/articles/PMC12739322/
A60: psicodelicos | B60: Nabilona | C60: Nabilona: quién responde (análisis post hoc) | D60: Perfil de respondedores | E60: Feldman OJ, Herrmann N, ... Lanctôt KL. 2026. Int Psychogeriatr | F60: ensayo aleatorizado | G60: Post hoc del cruzado de nabilona | H60: 39 | I60: Alzheimer moderado-grave con agitación | J60: Igual que el ensayo original | K60: Nabilona (ensayo original) | L60: Predictores de respuesta en CMAI | M60: Cinco rasgos con mayor eficacia: más dolor (PAINAD ≥3, diferencia CMAI -18,8), más trastorno de apetito (-16,4), más apatía (-14,0), menos deterioro (sMMSE >10; -16,5), sin inhibidores de colinesterasa (-13,9). Tercil superior predicho: respondió 82% vs 40% en el inferior; interacción F(2,29)=8,48; p=0,001 | N60: mejora | O60: No consta | P60: Autora KLL declara honorarios de consultoría de Bristol Myers Squibb, Eisai, Exciva, Lundbeck, Merck, Novo Nordisk y Praxis; SEB declara contratos con Genentech, Roche, Eli Lilly, Eisai/Biogen y otros | S60: cita encontrada; cifra coincide. PMID 41530008; DOI 10.1016/j.inpsyc.2026.100183 (82 % y 40 % presentes) | T60: PMID 41530008; DOI 10.1016/j.inpsyc.2026.100183 | U60: https://pubmed.ncbi.nlm.nih.gov/41530008/
A61: psicodelicos | B61: THC:CBD (aceite) | C61: THC:CBD aceite 1:2 (hasta 20 mg/40 mg al día) | D61: Cannabinoides en demencia grave, Ginebra | E61: Bianchi F, Broers B, Desmeules JA, ... Pautex S. 2026. Age Ageing | F61: ensayo aleatorizado | G61: Cruzado, doble ciego, placebo, 5 residencias; 2 periodos de 8 semanas | H61: 25 aleatorizados, 19 completaron ambos periodos (edad media 83) | I61: Demencia grave en residencias | J61: 8 semanas por periodo + 1 de lavado | K61: Aceite oral THC:CBD 1:2 hasta 20 mg/40 mg al día | L61: CMAI (primario); escalas de conducta, dolor, psicótropos a demanda | M61: Sin diferencia significativa en CMAI ni en las principales escalas de conducta. El uso de psicótropos a demanda (PRN) fue significativamente menor durante el tratamiento activo | N61: sin cambio | O61: Bien tolerado; sin eventos graves relacionados con el fármaco | P61: No consta en el resumen; registro NCT05432206 (Fondation pour l'accueil et l'hébergement des personnes âgées) | Q61: Dosis de la fuente: aceite oral THC:CBD 1:2, máximo 20 mg THC y 40 mg CBD al día | S61: cita encontrada; cifra no comprobable en el resumen. DOI 10.1093/ageing/afag239 -> PMID 42613673; NCT05432206 (el resumen no da n=25/19; el registro indica 27 inscritos; revisar) | T61: Age Ageing 2026; DOI 10.1093/ageing/afag239; NCT05432206 | U61: https://doi.org/10.1093/ageing/afag239
A62: psicodelicos | B62: Nabiximols | C62: Nabiximols (Sativex), espray oromucoso THC:CBD 1:1 | D62: Residencias de Reino Unido, factibilidad | E62: Albertyn CP, ... Aarsland D. 2025. Age Ageing (ensayo STAND) | F62: ensayo aleatorizado | G62: Factibilidad, doble ciego, placebo | H62: 29 aleatorizados (53 evaluados) | I62: Alzheimer con agitación en residencias | J62: 4 semanas de tratamiento + 4 de observación | K62: Nabiximols titulado, 4 semanas | L62: Factibilidad, seguridad, tamaño de efecto en CMAI | M62: Nadie abandonó; adherencia 100%; bien tolerado, 0 reacciones adversas; sin problemas de seguridad. Eficacia no analizada como resultado confirmatorio | N62: sin cambio | O62: 0 reacciones adversas notificadas | P62: No consta en el resumen | S62: cita encontrada; cifra coincide. PMID 40479610; DOI 10.1093/ageing/afaf149; ISRCTN 7163562 | T62: PMID 40479610; ISRCTN 7163562; DOI 10.1093/ageing/afaf149 | U62: https://pubmed.ncbi.nlm.nih.gov/40479610/
A63: psicodelicos | B63: Cannabidiol (CBD) | C63: Cannabidiol 300 mg/día | D63: Síntomas conductuales en demencia vascular; Brasil (USP Ribeirão Preto) | E63: Pessoa RMP, Zuardi AW, ... Chagas MHN. 2026. J Psychopharmacol | F63: ensayo aleatorizado | G63: Doble ciego, placebo | H63: 30 | I63: Demencia vascular con síntomas conductuales | J63: 4 semanas | K63: CBD 300 mg/día o placebo | L63: NPI y BPRS; MMSE, IQCODE, Katz, Lawton | M63: Reducción de NPI (interacción F(1,58;44,31)=3,61; p=0,05; eta parcial 0,11) y BPRS (F(2,12;59,43)=4,02; eta 0,13) vs placebo; sin diferencias en cognición ni función | N63: mejora | O63: Leves y similares entre grupos | P63: CNPq y CAPES (becas); conflictos no consta en el resumen. Registro ReBEC RBR-686kmpz | Q63: Dosis de la fuente: 300 mg/día de CBD durante 4 semanas | S63: cita encontrada; cifra coincide. PMID 41277041; DOI 10.1177/02698811251390974 (9 de 9 cifras presentes) | T63: PMID 41277041; DOI 10.1177/02698811251390974 | U63: https://pubmed.ncbi.nlm.nih.gov/41277041/
A64: psicodelicos | B64: Cannabis medicinal (THC) | C64: Aceite de cannabis medicinal (THC) añadido a la medicación | D64: Israel, hospital Abarbanel | E64: Shelef A, Barak Y, ... Baruch Y. 2016. J Alzheimers Dis | F64: ensayo no aleatorizado | G64: Abierto, piloto, prospectivo, 4 semanas | H64: 11 reclutados, 10 completaron | I64: Alzheimer con síntomas conductuales | J64: 4 semanas | K64: Aceite de cannabis medicinal con THC como añadido | L64: CGI de gravedad y NPI | M64: CGI gravedad 6,5 a 5,7 (p<0,01); NPI 44,4 a 12,8 (p<0,01); bajaron delirios, agitación/agresión, irritabilidad, apatía, sueño y malestar del cuidador | N64: mejora | O64: No detallados en el resumen | P64: No consta en el resumen | S64: cita encontrada; cifra coincide. PMID 26757043; DOI 10.3233/JAD-150915 (5 de 5 cifras presentes) | T64: PMID 26757043; DOI 10.3233/JAD-150915 | U64: https://pubmed.ncbi.nlm.nih.gov/26757043/
A65: psicodelicos | B65: Dronabinol | C65: Dronabinol para anorexia y conducta | D65: Apetito y peso en Alzheimer, años 90 | E65: Volicer L, Stelly M, Morris J, McLaughlin J, Volicer BJ. 1997. Int J Geriatr Psychiatry | F65: ensayo aleatorizado | G65: Cruzado, placebo, 6 semanas por periodo | H65: 15 (11 completaron ambos periodos) | I65: Alzheimer probable que rechazaba comida | J65: 12 semanas | K65: Dronabinol (dosis no consta en el resumen) | L65: Peso corporal y conducta alterada | M65: El peso aumentó más con dronabinol que con placebo; menor gravedad de conducta alterada, efecto que persistió en periodo placebo en quienes lo recibieron primero | N65: mejora | O65: Euforia, somnolencia y cansancio más con dronabinol. Se interrumpió en 3 pacientes: una crisis epiléptica y 2 infecciones graves intercurrentes; un fallecido por infarto 2 semanas antes del fin | P65: No consta | S65: cita encontrada; cifra no comprobable en el resumen. PMID 9309469; DOI 10.1002/(sici)1099-1166(199709)12:9<913::aid-gps663>3.0.co;2-d (título y año 1997 coinciden) | T65: PMID 9309469; DOI 10.1002/(sici)1099-1166(199709)12:9<913::aid-gps663>3.0.co;2-d | U65: https://pubmed.ncbi.nlm.nih.gov/9309469/
A66: psicodelicos | B66: THC (Namisol) | C66: THC oral 0,75 y 1,5 mg dos veces al día (Namisol) | D66: Farmacocinética de THC en demencia, Radboud, Países Bajos | E66: Ahmed AI, van den Elsen GA, ... Olde Rikkert MG. 2015. Psychopharmacology | F66: ensayo aleatorizado | G66: Cruzado, doble ciego, placebo | H66: 10 (edad media 77,3) | I66: Demencia | J66: 12 semanas (3 días de tratamiento por bloque, 4 de lavado) | K66: THC oral 0,75 mg (semanas 1-6) y 1,5 mg (semanas 7-12) dos veces al día | L66: Seguridad, farmacodinamia, farmacocinética | M66: Solo 6 de 98 eventos adversos relacionados con THC. Tras 0,75 mg: percepción interna +0,025 y frecuencia cardiaca +2 lpm; balanceo con ojos cerrados aumentó solo con 1,5 mg (0,59 grados/s); presión sistólica cambió (-7 mmHg con 0,75 mg; 5 mmHg con 1,5 mg). Cmax 0,41 ng/mL (0,75 mg) y 1,01 (1,5 mg) | N66: sin cambio | O66: Menores | P66: No consta en el resumen | S66: cita encontrada; cifra coincide. PMID 25752889; DOI 10.1007/s00213-015-3889-y (7 de 7 cifras presentes) | T66: PMID 25752889; DOI 10.1007/s00213-015-3889-y | U66: https://pubmed.ncbi.nlm.nih.gov/25752889/
A67: psicodelicos | B67: Cannabinoides (revisión) | C67: Cannabinoides en demencia (revisión Cochrane) | D67: Revisión sistemática 2021 | E67: Bosnjak Kuharic D, ... Puljak L. 2021. Cochrane Database Syst Rev | F67: revision | G67: Metaanálisis de efecto fijo | H67: 4 estudios, 126 participantes | I67: Alzheimer principalmente; algunos vasculares o mixtos | J67: 3 a 14 semanas (un estudio con eventos adversos a 70 semanas) | K67: THC natural (Namisol), dronabinol y nabilona | L67: Eficacia y seguridad | M67: El resumen leído lista los estudios, la duración y la financiación (dos con financiación no comercial, dos con comercial y no comercial); los resultados numéricos no estaban en el fragmento leído | N67: no aplica | O67: No leído en el fragmento | P67: Dos estudios con apoyo comercial y no comercial; dos solo no comercial | S67: cita encontrada; cifra no comprobable en el resumen. PMID 34532852; DOI 10.1002/14651858.CD012820.pub2 (título y año 2021 coinciden) | T67: PMID 34532852; DOI 10.1002/14651858.CD012820.pub2 | U67: https://pubmed.ncbi.nlm.nih.gov/34532852/
A68: psicodelicos | B68: Cannabinoides (revisión) | C68: Cannabinoides para agitación en Alzheimer (metaanálisis) | D68: Metaanálisis con análisis bayesiano y secuencial | E68: da Silva AMP, ... 2026. Am J Geriatr Psychiatry | F68: revision | G68: Revisión sistemática y metaanálisis, PROSPERO | H68: 7 estudios (6 aleatorizados), 221 participantes | I68: Alzheimer con agitación | J68: Cortas | K68: Cannabinoides varios | L68: NPI total, CMAI-SF, NPI agitación, MMSE, seguridad | M68: NPI total SMD -0,31 (IC95 -0,47 a -0,15; k=4); CMAI-SF SMD -0,40 (-0,69 a -0,10; k=3); NPI A/A SMD -0,47 (-0,69 a -0,25; k=3); sin beneficio cognitivo consistente en MMSE | N68: mejora | O68: Somnolencia: RR 2,25 (IC95 1,43-3,54); caídas y fatiga imprecisas | P68: No consta | S68: cita encontrada; cifra coincide. PMID 42315374; DOI 10.1016/j.jagp.2026.05.016 (8 de 8 cifras presentes) | T68: PMID 42315374; DOI 10.1016/j.jagp.2026.05.016 | U68: https://pubmed.ncbi.nlm.nih.gov/42315374/
A69: psicodelicos | B69: Nabilona | C69: Nabilona dosis baja 500 microgramos/día | D69: Caso clínico en Reino Unido | E69: Koneru A, Zarroug M. 2026. BJPsych Open (resumen de congreso RCPsych) | F69: caso | G69: Informe de caso | H69: 1 | I69: Varón de 73 años, Alzheimer de inicio tardío, CDR 2, sMMSE 13/30 | J69: 3 semanas de seguimiento | K69: Nabilona 500 microgramos diarios (tras fallo de otros fármacos); intento de bajar a 250 mantuvo síntomas peores | L69: NPI | M69: NPI frecuencia y gravedad 51 a 9 y malestar 21 a 5 tras 3 semanas. Al reducir a 250 microgramos empeoró y se volvió a 500 | N69: mejora | O69: Sin efectos secundarios duraderos significativos según el autor | P69: No consta; resumen no revisado por pares estándar de BJPsych Open | Q69: Dosis de la fuente: 500 microgramos al día oral | S69: cita encontrada; cifra no comprobable en el resumen. PMCID PMC13328946 (título coincide: caso de nabilona 'Use of Low Dose Nabilone to Manage BPSD'; sin año en Europe PMC) | T69: PMCID PMC13328946 | U69: https://pmc.ncbi.nlm.nih.gov/articles/PMC13328946/
A70: psicodelicos | B70: Piracetam | C70: Piracetam 8 g/día un año | D70: Nootrópico clásico en Alzheimer | E70: Croisile B, Trillet M, ... Billardon M. 1993. Neurology | F70: ensayo aleatorizado | G70: Paralelo, doble ciego, placebo | H70: 33 (30 completaron) | I70: Alzheimer probable temprano, ambulatorios | J70: 1 año | K70: Piracetam 8 g/día por vía oral | L70: Cognición y memoria | M70: Sin mejora en ningún grupo, pero los autores indican que la administración prolongada de dosis altas podría frenar la progresión; diferencias más significativas en recuerdo de series de imágenes y memoria reciente y remota | N70: mixto | O70: Bien tolerado | P70: No consta | Q70: Dosis de la fuente: 8 g/día | S70: cita encontrada; cifra coincide. PMID 8437693; DOI 10.1212/wnl.43.2.301 (8 g/d presente) | T70: PMID 8437693; DOI 10.1212/wnl.43.2.301 | U70: https://pubmed.ncbi.nlm.nih.gov/8437693/
A71: psicodelicos | B71: Nootrópicos | C71: Nootrópicos (piracetam, aniracetam, nimodipino, dihidroergocristina) vs inhibidores de colinesterasa | D71: Estudio retrospectivo en Grecia | E71: Tsolaki M, Pantazi T, Kazis A. 2001. J Int Med Res | F71: observacional | G71: Retrospectivo longitudinal | H71: 510 | I71: Alzheimer | J71: 12 meses | K71: Nootrópicos frente a tacrina o donepezilo | L71: MMSE, CAMCOG, escala funcional | M71: Sin diferencia en el total ni en grave. En demencia moderada (MMSE 11-20) mayor deterioro en CAMCOG con inhibidores (-4,38) que con nootrópicos (+1,48). En leve (MMSE 21-26) mayor deterioro en MMSE con nootrópicos. Los autores: sin evidencia fuerte de diferencia | N71: mixto | O71: No consta | P71: No consta | S71: cita encontrada; cifra coincide. PMID 11277345; DOI 10.1177/147323000102900105 (6 de 6 cifras presentes) | T71: PMID 11277345; DOI 10.1177/147323000102900105 | U71: https://pubmed.ncbi.nlm.nih.gov/11277345/
...

Sheet Resumen
A1: Tema | B1: Intervención (grupo) | C1: Nº estudios o fuentes | D1: Mejora | E1: Sin cambio | F1: Empeora | G1: Mixto | H1: Citas encontradas | I1: Citas no encontradas
A2: cobre_metales | B2: Cobre (suplemento oral) | C2: =COUNTIFS(Filas!$A$2:$A$648,$A2,Filas!$B$2:$B$648,$B2) -> 2 | D2: =COUNTIFS(Filas!$A$2:$A$648,$A2,Filas!$B$2:$B$648,$B2,Filas!$N$2:$N$648,"mejora") -> 0 | E2: =COUNTIFS(Filas!$A$2:$A$648,$A2,Filas!$B$2:$B$648,$B2,Filas!$N$2:$N$648,"sin cambio") -> 1 | F2: =COUNTIFS(Filas!$A$2:$A$648,$A2,Filas!$B$2:$B$648,$B2,Filas!$N$2:$N$648,"empeora") -> 0 | G2: =COUNTIFS(Filas!$A$2:$A$648,$A2,Filas!$B$2:$B$648,$B2,Filas!$N$2:$N$648,"mixto") -> 1 | H2: =COUNTIFS(Filas!$A$2:$A$648,$A2,Filas!$B$2:$B$648,$B2,Filas!$S$2:$S$648,"cita encontrada*")+COUNTIFS(Filas!$A$2:$A$648,$A2,Filas!$B$2:$B$648,$B2,Filas!$S$2:$S$648,"página existe*") -> 2 | I2: =COUNTIFS(Filas!$A$2:$A$648,$A2,Filas!$B$2:$B$648,$B2,Filas!$S$2:$S$648,"cita no encontrada*")+COUNTIFS(Filas!$A$2:$A$648,$A2,Filas!$B$2:$B$648,$B2,Filas!$S$2:$S$648,"página no accesible*") -> 0
A3: cobre_metales | B3: Cobre (agua de bebida) | C3: =COUNTIFS(Filas!$A$2:$A$648,$A3,Filas!$B$2:$B$648,$B3) -> 1 | D3: =COUNTIFS(Filas!$A$2:$A$648,$A3,Filas!$B$2:$B$648,$B3,Filas!$N$2:$N$648,"mejora") -> 0 | E3: =COUNTIFS(Filas!$A$2:$A$648,$A3,Filas!$B$2:$B$648,$B3,Filas!$N$2:$N$648,"sin cambio") -> 0 | F3: =COUNTIFS(Filas!$A$2:$A$648,$A3,Filas!$B$2:$B$648,$B3,Filas!$N$2:$N$648,"empeora") -> 1 | G3: =COUNTIFS(Filas!$A$2:$A$648,$A3,Filas!$B$2:$B$648,$B3,Filas!$N$2:$N$648,"mixto") -> 0 | H3: =COUNTIFS(Filas!$A$2:$A$648,$A3,Filas!$B$2:$B$648,$B3,Filas!$S$2:$S$648,"cita encontrada*")+COUNTIFS(Filas!$A$2:$A$648,$A3,Filas!$B$2:$B$648,$B3,Filas!$S$2:$S$648,"página existe*") -> 1 | I3: =COUNTIFS(Filas!$A$2:$A$648,$A3,Filas!$B$2:$B$648,$B3,Filas!$S$2:$S$648,"cita no encontrada*")+COUNTIFS(Filas!$A$2:$A$648,$A3,Filas!$B$2:$B$648,$B3,Filas!$S$2:$S$648,"página no accesible*") -> 0
A4: cobre_metales | B4: Cobre (biomarcadores) | C4: =COUNTIFS(Filas!$A$2:$A$648,$A4,Filas!$B$2:$B$648,$B4) -> 3 | D4: =COUNTIFS(Filas!$A$2:$A$648,$A4,Filas!$B$2:$B$648,$B4,Filas!$N$2:$N$648,"mejora") -> 0 | E4: =COUNTIFS(Filas!$A$2:$A$648,$A4,Filas!$B$2:$B$648,$B4,Filas!$N$2:$N$648,"sin cambio") -> 0 | F4: =COUNTIFS(Filas!$A$2:$A$648,$A4,Filas!$B$2:$B$648,$B4,Filas!$N$2:$N$648,"empeora") -> 2 | G4: =COUNTIFS(Filas!$A$2:$A$648,$A4,Filas!$B$2:$B$648,$B4,Filas!$N$2:$N$648,"mixto") -> 1 | H4: =COUNTIFS(Filas!$A$2:$A$648,$A4,Filas!$B$2:$B$648,$B4,Filas!$S$2:$S$648,"cita encontrada*")+COUNTIFS(Filas!$A$2:$A$648,$A4,Filas!$B$2:$B$648,$B4,Filas!$S$2:$S$648,"página existe*") -> 3 | I4: =COUNTIFS(Filas!$A$2:$A$648,$A4,Filas!$B$2:$B$648,$B4,Filas!$S$2:$S$648,"cita no encontrada*")+COUNTIFS(Filas!$A$2:$A$648,$A4,Filas!$B$2:$B$648,$B4,Filas!$S$2:$S$648,"página no accesible*") -> 0
A5: cobre_metales | B5: Cobre (dieta) | C5: =COUNTIFS(Filas!$A$2:$A$648,$A5,Filas!$B$2:$B$648,$B5) -> 1 | D5: =COUNTIFS(Filas!$A$2:$A$648,$A5,Filas!$B$2:$B$648,$B5,Filas!$N$2:$N$648,"mejora") -> 0 | E5: =COUNTIFS(Filas!$A$2:$A$648,$A5,Filas!$B$2:$B$648,$B5,Filas!$N$2:$N$648,"sin cambio") -> 0 | F5: =COUNTIFS(Filas!$A$2:$A$648,$A5,Filas!$B$2:$B$648,$B5,Filas!$N$2:$N$648,"empeora") -> 0 | G5: =COUNTIFS(Filas!$A$2:$A$648,$A5,Filas!$B$2:$B$648,$B5,Filas!$N$2:$N$648,"mixto") -> 1 | H5: =COUNTIFS(Filas!$A$2:$A$648,$A5,Filas!$B$2:$B$648,$B5,Filas!$S$2:$S$648,"cita encontrada*")+COUNTIFS(Filas!$A$2:$A$648,$A5,Filas!$B$2:$B$648,$B5,Filas!$S$2:$S$648,"página existe*") -> 1 | I5: =COUNTIFS(Filas!$A$2:$A$648,$A5,Filas!$B$2:$B$648,$B5,Filas!$S$2:$S$648,"cita no encontrada*")+COUNTIFS(Filas!$A$2:$A$648,$A5,Filas!$B$2:$B$648,$B5,Filas!$S$2:$S$648,"página no accesible*") -> 0
A6: cobre_metales | B6: Cobre (evitar exposición) | C6: =COUNTIFS(Filas!$A$2:$A$648,$A6,Filas!$B$2:$B$648,$B6) -> 1 | D6: =COUNTIFS(Filas!$A$2:$A$648,$A6,Filas!$B$2:$B$648,$B6,Filas!$N$2:$N$648,"mejora") -> 1 | E6: =COUNTIFS(Filas!$A$2:$A$648,$A6,Filas!$B$2:$B$648,$B6,Filas!$N$2:$N$648,"sin cambio") -> 0 | F6: =COUNTIFS(Filas!$A$2:$A$648,$A6,Filas!$B$2:$B$648,$B6,Filas!$N$2:$N$648,"empeora") -> 0 | G6: =COUNTIFS(Filas!$A$2:$A$648,$A6,Filas!$B$2:$B$648,$B6,Filas!$N$2:$N$648,"mixto") -> 0 | H6: =COUNTIFS(Filas!$A$2:$A$648,$A6,Filas!$B$2:$B$648,$B6,Filas!$S$2:$S$648,"cita encontrada*")+COUNTIFS(Filas!$A$2:$A$648,$A6,Filas!$B$2:$B$648,$B6,Filas!$S$2:$S$648,"página existe*") -> 1 | I6: =COUNTIFS(Filas!$A$2:$A$648,$A6,Filas!$B$2:$B$648,$B6,Filas!$S$2:$S$648,"cita no encontrada*")+COUNTIFS(Filas!$A$2:$A$648,$A6,Filas!$B$2:$B$648,$B6,Filas!$S$2:$S$648,"página no accesible*") -> 0
A7: cobre_metales | B7: Zinc (suplemento) | C7: =COUNTIFS(Filas!$A$2:$A$648,$A7,Filas!$B$2:$B$648,$B7) -> 2 | D7: =COUNTIFS(Filas!$A$2:$A$648,$A7,Filas!$B$2:$B$648,$B7,Filas!$N$2:$N$648,"mejora") -> 0 | E7: =COUNTIFS(Filas!$A$2:$A$648,$A7,Filas!$B$2:$B$648,$B7,Filas!$N$2:$N$648,"sin cambio") -> 0 | F7: =COUNTIFS(Filas!$A$2:$A$648,$A7,Filas!$B$2:$B$648,$B7,Filas!$N$2:$N$648,"empeora") -> 0 | G7: =COUNTIFS(Filas!$A$2:$A$648,$A7,Filas!$B$2:$B$648,$B7,Filas!$N$2:$N$648,"mixto") -> 1 | H7: =COUNTIFS(Filas!$A$2:$A$648,$A7,Filas!$B$2:$B$648,$B7,Filas!$S$2:$S$648,"cita encontrada*")+COUNTIFS(Filas!$A$2:$A$648,$A7,Filas!$B$2:$B$648,$B7,Filas!$S$2:$S$648,"página existe*") -> 2 | I7: =COUNTIFS(Filas!$A$2:$A$648,$A7,Filas!$B$2:$B$648,$B7,Filas!$S$2:$S$648,"cita no encontrada*")+COUNTIFS(Filas!$A$2:$A$648,$A7,Filas!$B$2:$B$648,$B7,Filas!$S$2:$S$648,"página no accesible*") -> 0
A8: cobre_metales | B8: Zinc (biomarcadores) | C8: =COUNTIFS(Filas!$A$2:$A$648,$A8,Filas!$B$2:$B$648,$B8) -> 2 | D8: =COUNTIFS(Filas!$A$2:$A$648,$A8,Filas!$B$2:$B$648,$B8,Filas!$N$2:$N$648,"mejora") -> 0 | E8: =COUNTIFS(Filas!$A$2:$A$648,$A8,Filas!$B$2:$B$648,$B8,Filas!$N$2:$N$648,"sin cambio") -> 0 | F8: =COUNTIFS(Filas!$A$2:$A$648,$A8,Filas!$B$2:$B$648,$B8,Filas!$N$2:$N$648,"empeora") -> 1 | G8: =COUNTIFS(Filas!$A$2:$A$648,$A8,Filas!$B$2:$B$648,$B8,Filas!$N$2:$N$648,"mixto") -> 1 | H8: =COUNTIFS(Filas!$A$2:$A$648,$A8,Filas!$B$2:$B$648,$B8,Filas!$S$2:$S$648,"cita encontrada*")+COUNTIFS(Filas!$A$2:$A$648,$A8,Filas!$B$2:$B$648,$B8,Filas!$S$2:$S$648,"página existe*") -> 2 | I8: =COUNTIFS(Filas!$A$2:$A$648,$A8,Filas!$B$2:$B$648,$B8,Filas!$S$2:$S$648,"cita no encontrada*")+COUNTIFS(Filas!$A$2:$A$648,$A8,Filas!$B$2:$B$648,$B8,Filas!$S$2:$S$648,"página no accesible*") -> 0
A9: cobre_metales | B9: Clioquinol | C9: =COUNTIFS(Filas!$A$2:$A$648,$A9,Filas!$B$2:$B$648,$B9) -> 1 | D9: =COUNTIFS(Filas!$A$2:$A$648,$A9,Filas!$B$2:$B$648,$B9,Filas!$N$2:$N$648,"mejora") -> 1 | E9: =COUNTIFS(Filas!$A$2:$A$648,$A9,Filas!$B$2:$B$648,$B9,Filas!$N$2:$N$648,"sin cambio") -> 0 | F9: =COUNTIFS(Filas!$A$2:$A$648,$A9,Filas!$B$2:$B$648,$B9,Filas!$N$2:$N$648,"empeora") -> 0 | G9: =COUNTIFS(Filas!$A$2:$A$648,$A9,Filas!$B$2:$B$648,$B9,Filas!$N$2:$N$648,"mixto") -> 0 | H9: =COUNTIFS(Filas!$A$2:$A$648,$A9,Filas!$B$2:$B$648,$B9,Filas!$S$2:$S$648,"cita encontrada*")+COUNTIFS(Filas!$A$2:$A$648,$A9,Filas!$B$2:$B$648,$B9,Filas!$S$2:$S$648,"página existe*") -> 1 | I9: =COUNTIFS(Filas!$A$2:$A$648,$A9,Filas!$B$2:$B$648,$B9,Filas!$S$2:$S$648,"cita no encontrada*")+COUNTIFS(Filas!$A$2:$A$648,$A9,Filas!$B$2:$B$648,$B9,Filas!$S$2:$S$648,"página no accesible*") -> 0
A10: cobre_metales | B10: PBT2 (ionóforo Cu/Zn) | C10: =COUNTIFS(Filas!$A$2:$A$648,$A10,Filas!$B$2:$B$648,$B10) -> 2 | D10: =COUNTIFS(Filas!$A$2:$A$648,$A10,Filas!$B$2:$B$648,$B10,Filas!$N$2:$N$648,"mejora") -> 1 | E10: =COUNTIFS(Filas!$A$2:$A$648,$A10,Filas!$B$2:$B$648,$B10,Filas!$N$2:$N$648,"sin cambio") -> 0 | F10: =COUNTIFS(Filas!$A$2:$A$648,$A10,Filas!$B$2:$B$648,$B10,Filas!$N$2:$N$648,"empeora") -> 0 | G10: =COUNTIFS(Filas!$A$2:$A$648,$A10,Filas!$B$2:$B$648,$B10,Filas!$N$2:$N$648,"mixto") -> 1 | H10: =COUNTIFS(Filas!$A$2:$A$648,$A10,Filas!$B$2:$B$648,$B10,Filas!$S$2:$S$648,"cita encontrada*")+COUNTIFS(Filas!$A$2:$A$648,$A10,Filas!$B$2:$B$648,$B10,Filas!$S$2:$S$648,"página existe*") -> 2 | I10: =COUNTIFS(Filas!$A$2:$A$648,$A10,Filas!$B$2:$B$648,$B10,Filas!$S$2:$S$648,"cita no encontrada*")+COUNTIFS(Filas!$A$2:$A$648,$A10,Filas!$B$2:$B$648,$B10,Filas!$S$2:$S$648,"página no accesible*") -> 0
A11: cobre_metales | B11: Desferrioxamina | C11: =COUNTIFS(Filas!$A$2:$A$648,$A11,Filas!$B$2:$B$648,$B11) -> 1 | D11: =COUNTIFS(Filas!$A$2:$A$648,$A11,Filas!$B$2:$B$648,$B11,Filas!$N$2:$N$648,"mejora") -> 1 | E11: =COUNTIFS(Filas!$A$2:$A$648,$A11,Filas!$B$2:$B$648,$B11,Filas!$N$2:$N$648,"sin cambio") -> 0 | F11: =COUNTIFS(Filas!$A$2:$A$648,$A11,Filas!$B$2:$B$648,$B11,Filas!$N$2:$N$648,"empeora") -> 0 | G11: =COUNTIFS(Filas!$A$2:$A$648,$A11,Filas!$B$2:$B$648,$B11,Filas!$N$2:$N$648,"mixto") -> 0 | H11: =COUNTIFS(Filas!$A$2:$A$648,$A11,Filas!$B$2:$B$648,$B11,Filas!$S$2:$S$648,"cita encontrada*")+COUNTIFS(Filas!$A$2:$A$648,$A11,Filas!$B$2:$B$648,$B11,Filas!$S$2:$S$648,"página existe*") -> 1 | I11: =COUNTIFS(Filas!$A$2:$A$648,$A11,Filas!$B$2:$B$648,$B11,Filas!$S$2:$S$648,"cita no encontrada*")+COUNTIFS(Filas!$A$2:$A$648,$A11,Filas!$B$2:$B$648,$B11,Filas!$S$2:$S$648,"página no accesible*") -> 0
A12: cobre_metales | B12: Deferiprona | C12: =COUNTIFS(Filas!$A$2:$A$648,$A12,Filas!$B$2:$B$648,$B12) -> 1 | D12: =COUNTIFS(Filas!$A$2:$A$648,$A12,Filas!$B$2:$B$648,$B12,Filas!$N$2:$N$648,"mejora") -> 0 | E12: =COUNTIFS(Filas!$A$2:$A$648,$A12,Filas!$B$2:$B$648,$B12,Filas!$N$2:$N$648,"sin cambio") -> 0 | F12: =COUNTIFS(Filas!$A$2:$A$648,$A12,Filas!$B$2:$B$648,$B12,Filas!$N$2:$N$648,"empeora") -> 1 | G12: =COUNTIFS(Filas!$A$2:$A$648,$A12,Filas!$B$2:$B$648,$B12,Filas!$N$2:$N$648,"mixto") -> 0 | H12: =COUNTIFS(Filas!$A$2:$A$648,$A12,Filas!$B$2:$B$648,$B12,Filas!$S$2:$S$648,"cita encontrada*")+COUNTIFS(Filas!$A$2:$A$648,$A12,Filas!$B$2:$B$648,$B12,Filas!$S$2:$S$648,"página existe*") -> 1 | I12: =COUNTIFS(Filas!$A$2:$A$648,$A12,Filas!$B$2:$B$648,$B12,Filas!$S$2:$S$648,"cita no encontrada*")+COUNTIFS(Filas!$A$2:$A$648,$A12,Filas!$B$2:$B$648,$B12,Filas!$S$2:$S$648,"página no accesible*") -> 0
A13: cobre_metales | B13: Agua rica en silicio | C13: =COUNTIFS(Filas!$A$2:$A$648,$A13,Filas!$B$2:$B$648,$B13) -> 1 | D13: =COUNTIFS(Filas!$A$2:$A$648,$A13,Filas!$B$2:$B$648,$B13,Filas!$N$2:$N$648,"mejora") -> 1 | E13: =COUNTIFS(Filas!$A$2:$A$648,$A13,Filas!$B$2:$B$648,$B13,Filas!$N$2:$N$648,"sin cambio") -> 0 | F13: =COUNTIFS(Filas!$A$2:$A$648,$A13,Filas!$B$2:$B$648,$B13,Filas!$N$2:$N$648,"empeora") -> 0 | G13: =COUNTIFS(Filas!$A$2:$A$648,$A13,Filas!$B$2:$B$648,$B13,Filas!$N$2:$N$648,"mixto") -> 0 | H13: =COUNTIFS(Filas!$A$2:$A$648,$A13,Filas!$B$2:$B$648,$B13,Filas!$S$2:$S$648,"cita encontrada*")+COUNTIFS(Filas!$A$2:$A$648,$A13,Filas!$B$2:$B$648,$B13,Filas!$S$2:$S$648,"página existe*") -> 1 | I13: =COUNTIFS(Filas!$A$2:$A$648,$A13,Filas!$B$2:$B$648,$B13,Filas!$S$2:$S$648,"cita no encontrada*")+COUNTIFS(Filas!$A$2:$A$648,$A13,Filas!$B$2:$B$648,$B13,Filas!$S$2:$S$648,"página no accesible*") -> 0
... A354: relatos_familias | B354: Índice GreenMedInfo (sin intervención) | C354: =COUNTIFS(Filas!$A$2:$A$648,$A354,Filas!$B$2:$B$648,$B354) -> 1 | D354: =COUNTIFS(Filas!$A$2:$A$648,$A354,Filas!$B$2:$B$648,$B354,Filas!$N$2:$N$648,"mejora") -> 0 | E354: =COUNTIFS(Filas!$A$2:$A$648,$A354,Filas!$B$2:$B$648,$B354,Filas!$N$2:$N$648,"sin cambio") -> 0 | F354: =COUNTIFS(Filas!$A$2:$A$648,$A354,Filas!$B$2:$B$648,$B354,Filas!$N$2:$N$648,"empeora") -> 0 | G354: =COUNTIFS(Filas!$A$2:$A$648,$A354,Filas!$B$2:$B$648,$B354,Filas!$N$2:$N$648,"mixto") -> 0 | H354: =COUNTIFS(Filas!$A$2:$A$648,$A354,Filas!$B$2:$B$648,$B354,Filas!$S$2:$S$648,"cita encontrada*")+COUNTIFS(Filas!$A$2:$A$648,$A354,Filas!$B$2:$B$648,$B354,Filas!$S$2:$S$648,"página existe*") -> 1 | I354: =COUNTIFS(Filas!$A$2:$A$648,$A354,Filas!$B$2:$B$648,$B354,Filas!$S$2:$S$648,"cita no encontrada*")+COUNTIFS(Filas!$A$2:$A$648,$A354,Filas!$B$2:$B$648,$B354,Filas!$S$2:$S$648,"página no accesible*") -> 0
B355: TOTAL | C355: =SUM(C2:C354) -> 647 | D355: =SUM(D2:D354) -> 322 | E355: =SUM(E2:E354) -> 61 | F355: =SUM(F2:F354) -> 38 | G355: =SUM(G2:G354) -> 120 | H355: =SUM(H2:H354) -> 641 | I355: =SUM(I2:I354) -> 6

Sheet Dosieres
A1: Tema | B1: Título | C1: Tesis | D1: Defensores | E1: Mecanismos propuestos | F1: Consenso y quién lo paga | G1: Lo enterrado | H1: Protocolos reportados | I1: Riesgos reconocidos por defensores | J1: Fuentes heterodoxas | K1: Ideas para la app | L1: Notas del investigador
